actionid: flake8
msg: getenv
cmdargs: ['/home/xedaq/anaconda3/bin/python', '-m', 'virtualenv', '--python', '/home/xedaq/anaconda3/bin/python', 'flake8']
env: {'LC_PAPER': 'it_IT.UTF-8', 'M2_HOME': '/usr/local/maven', 'VIRTUAL_ENV': '/home/xedaq/lax/.tox/flake8', '_': '/home/xedaq/anaconda3/bin/tox', 'PYTHONHASHSEED': '3590564184', 'LC_MONETARY': 'it_IT.UTF-8', 'SSH_CLIENT': '192.168.131.1 37684 22', 'TERM': 'xterm-256color', 'XDG_SESSION_ID': '52', 'SHLVL': '1', 'LC_NAME': 'it_IT.UTF-8', 'PYTHONPATH': '/home/xedaq/lax:/home/xedaq/lax/lax', 'LC_TIME': 'it_IT.UTF-8', 'MAIL': '/var/mail/xedaq', 'LD_LIBRARY_PATH': '/usr/local/lib:', 'LESSCLOSE': '/usr/bin/lesspipe %s %s', 'LC_MEASUREMENT': 'it_IT.UTF-8', 'LANGUAGE': 'en_GB:en', 'LC_TELEPHONE': 'it_IT.UTF-8', 'SHELL': '/bin/bash', 'HOME': '/home/xedaq', 'LANG': 'en_GB.UTF-8', 'PWD': '/home/xedaq/lax', 'LC_NUMERIC': 'it_IT.UTF-8', 'LC_ADDRESS': 'it_IT.UTF-8', 'LOGNAME': 'xedaq', 'XDG_RUNTIME_DIR': '/run/user/1000', 'LESSOPEN': '| /usr/bin/lesspipe %s', 'LS_COLORS': 'rs=0:di=01;34:ln=01;36:mh=00:pi=40;33:so=01;35:do=01;35:bd=40;33;01:cd=40;33;01:or=40;31;01:su=37;41:sg=30;43:ca=30;41:tw=30;42:ow=34;42:st=37;44:ex=01;32:*.tar=01;31:*.tgz=01;31:*.arj=01;31:*.taz=01;31:*.lzh=01;31:*.lzma=01;31:*.tlz=01;31:*.txz=01;31:*.zip=01;31:*.z=01;31:*.Z=01;31:*.dz=01;31:*.gz=01;31:*.lz=01;31:*.xz=01;31:*.bz2=01;31:*.bz=01;31:*.tbz=01;31:*.tbz2=01;31:*.tz=01;31:*.deb=01;31:*.rpm=01;31:*.jar=01;31:*.war=01;31:*.ear=01;31:*.sar=01;31:*.rar=01;31:*.ace=01;31:*.zoo=01;31:*.cpio=01;31:*.7z=01;31:*.rz=01;31:*.jpg=01;35:*.jpeg=01;35:*.gif=01;35:*.bmp=01;35:*.pbm=01;35:*.pgm=01;35:*.ppm=01;35:*.tga=01;35:*.xbm=01;35:*.xpm=01;35:*.tif=01;35:*.tiff=01;35:*.png=01;35:*.svg=01;35:*.svgz=01;35:*.mng=01;35:*.pcx=01;35:*.mov=01;35:*.mpg=01;35:*.mpeg=01;35:*.m2v=01;35:*.mkv=01;35:*.webm=01;35:*.ogm=01;35:*.mp4=01;35:*.m4v=01;35:*.mp4v=01;35:*.vob=01;35:*.qt=01;35:*.nuv=01;35:*.wmv=01;35:*.asf=01;35:*.rm=01;35:*.rmvb=01;35:*.flc=01;35:*.avi=01;35:*.fli=01;35:*.flv=01;35:*.gl=01;35:*.dl=01;35:*.xcf=01;35:*.xwd=01;35:*.yuv=01;35:*.cgm=01;35:*.emf=01;35:*.axv=01;35:*.anx=01;35:*.ogv=01;35:*.ogx=01;35:*.aac=00;36:*.au=00;36:*.flac=00;36:*.mid=00;36:*.midi=00;36:*.mka=00;36:*.mp3=00;36:*.mpc=00;36:*.ogg=00;36:*.ra=00;36:*.wav=00;36:*.axa=00;36:*.oga=00;36:*.spx=00;36:*.xspf=00;36:', 'USER': 'xedaq', 'MONGO_PASSWORD': 'luxstinks', 'SSH_CONNECTION': '192.168.131.1 37684 192.168.131.15 22', 'PATH': '/home/xedaq/lax/.tox/flake8/bin:/home/xedaq/anaconda3/bin:/home/xedaq/anaconda3/bin:/var/lib/mongodb-mms-automation/bin:/usr/local/maven/bin:/usr/local/sbin:/usr/local/bin:/usr/sbin:/usr/bin:/sbin:/bin:/usr/games:/usr/local/games', 'LC_IDENTIFICATION': 'it_IT.UTF-8', 'OLDPWD': '/home/xedaq', 'SSH_TTY': '/dev/pts/0'}

Already using interpreter /home/xedaq/anaconda3/bin/python
Using base prefix '/home/xedaq/anaconda3'
New python executable in /home/xedaq/lax/.tox/flake8/bin/python
Installing setuptools, pip, wheel...
  Complete output from command /home/xedaq/lax/.tox/flake8/bin/python - setuptools pip wheel:
  Exception:
Traceback (most recent call last):
  File "/home/xedaq/anaconda3/lib/python3.4/site-packages/virtualenv_support/pip-9.0.1-py2.py3-none-any.whl/pip/basecommand.py", line 215, in main
    status = self.run(options, args)
  File "/home/xedaq/anaconda3/lib/python3.4/site-packages/virtualenv_support/pip-9.0.1-py2.py3-none-any.whl/pip/commands/install.py", line 272, in run
    with self._build_session(options) as session:
  File "/home/xedaq/anaconda3/lib/python3.4/site-packages/virtualenv_support/pip-9.0.1-py2.py3-none-any.whl/pip/basecommand.py", line 72, in _build_session
    insecure_hosts=options.trusted_hosts,
  File "/home/xedaq/anaconda3/lib/python3.4/site-packages/virtualenv_support/pip-9.0.1-py2.py3-none-any.whl/pip/download.py", line 329, in __init__
    self.headers["User-Agent"] = user_agent()
  File "/home/xedaq/anaconda3/lib/python3.4/site-packages/virtualenv_support/pip-9.0.1-py2.py3-none-any.whl/pip/download.py", line 69, in user_agent
    "python": platform.python_version(),
  File "/home/xedaq/anaconda3/lib/python3.4/platform.py", line 1284, in python_version
    return _sys_version()[1]
  File "/home/xedaq/anaconda3/lib/python3.4/platform.py", line 1237, in _sys_version
    repr(sys_version))
ValueError: failed to parse CPython sys.version: '3.4.3 (default, Oct 14 2015, 20:31:36) \n[GCC 4.8.4]'
Traceback (most recent call last):
  File "<stdin>", line 23, in <module>
  File "/home/xedaq/anaconda3/lib/python3.4/site-packages/virtualenv_support/pip-9.0.1-py2.py3-none-any.whl/pip/__init__.py", line 233, in main
  File "/home/xedaq/anaconda3/lib/python3.4/site-packages/virtualenv_support/pip-9.0.1-py2.py3-none-any.whl/pip/basecommand.py", line 251, in main
  File "/home/xedaq/anaconda3/lib/python3.4/site-packages/virtualenv_support/pip-9.0.1-py2.py3-none-any.whl/pip/basecommand.py", line 72, in _build_session
  File "/home/xedaq/anaconda3/lib/python3.4/site-packages/virtualenv_support/pip-9.0.1-py2.py3-none-any.whl/pip/download.py", line 329, in __init__
  File "/home/xedaq/anaconda3/lib/python3.4/site-packages/virtualenv_support/pip-9.0.1-py2.py3-none-any.whl/pip/download.py", line 69, in user_agent
  File "/home/xedaq/anaconda3/lib/python3.4/platform.py", line 1284, in python_version
    return _sys_version()[1]
  File "/home/xedaq/anaconda3/lib/python3.4/platform.py", line 1237, in _sys_version
    repr(sys_version))
ValueError: failed to parse CPython sys.version: '3.4.3 (default, Oct 14 2015, 20:31:36) \n[GCC 4.8.4]'
----------------------------------------
...Installing setuptools, pip, wheel...done.
Traceback (most recent call last):
  File "/home/xedaq/anaconda3/lib/python3.4/runpy.py", line 170, in _run_module_as_main
    "__main__", mod_spec)
  File "/home/xedaq/anaconda3/lib/python3.4/runpy.py", line 85, in _run_code
    exec(code, run_globals)
  File "/home/xedaq/anaconda3/lib/python3.4/site-packages/virtualenv.py", line 2328, in <module>
    main()
  File "/home/xedaq/anaconda3/lib/python3.4/site-packages/virtualenv.py", line 713, in main
    symlink=options.symlink)
  File "/home/xedaq/anaconda3/lib/python3.4/site-packages/virtualenv.py", line 945, in create_environment
    download=download,
  File "/home/xedaq/anaconda3/lib/python3.4/site-packages/virtualenv.py", line 901, in install_wheel
    call_subprocess(cmd, show_stdout=False, extra_env=env, stdin=SCRIPT)
  File "/home/xedaq/anaconda3/lib/python3.4/site-packages/virtualenv.py", line 797, in call_subprocess
    % (cmd_desc, proc.returncode))
OSError: Command /home/xedaq/lax/.tox/flake8/bin/python - setuptools pip wheel failed with error code 1
